<?xml version="1.0"?>
<robot name="3dof_arm">

  <!-- Base Link -->
  <link name="base_link" />

  <!-- Link 1 -->
  <link name="link_1" />
  <joint name="joint_1" type="revolute">
    <parent link="base_link" />
    <child link="link_1" />
    <origin xyz="0 0 0.1" rpy="0 0 0" />
    <axis xyz="0 1 0" />
    <limit effort="10.0" lower="-1.57" upper="1.57" velocity="1.0" />
  </joint>

  <!-- Link 2 -->
  <link name="link_2" />
  <joint name="joint_2" type="revolute">
    <parent link="link_1" />
    <child link="link_2" />
    <origin xyz="0.5 0 0" rpy="0 0 0" />
    <axis xyz="0 1 0" />
    <limit effort="10.0" lower="-1.57" upper="1.57" velocity="1.0" />
  </joint>

  <!-- Link 3 -->
  <link name="link_3" />
  <joint name="joint_3" type="revolute">
    <parent link="link_2" />
    <child link="link_3" />
    <origin xyz="0.5 0 0" rpy="0 0 0" />
    <axis xyz="0 0 1" />
    <limit effort="10.0" lower="-1.57" upper="1.57" velocity="1.0" />
  </joint>

</robot>
