<?xml version="1.0"?>
<robot name="wheeled_robot_with_lift">
    <!-- Material Definitions -->
    <material name="blue">
        <color rgba="0 0 0.8 1"/>
    </material>

    <material name="black">
        <color rgba="0.1 0.1 0.1 1"/>
    </material>

    <material name="red">
        <color rgba="0.8 0 0 1"/>
    </material>

    <!-- Base Link -->
    <link name="base_link">
        <visual>
            <geometry>
                <box size="0.5 0.3 0.1"/>
            </geometry>
            <material name="blue"/>
        </visual>
        <collision>
            <geometry>
                <box size="0.5 0.3 0.1"/>
            </geometry>
        </collision>
        <inertial>
            <mass value="5.0"/>
            <origin xyz="0 0 0" rpy="0 0 0"/>
            <inertia ixx="0.1" ixy="0.0" ixz="0.0" 
                    iyy="0.1" iyz="0.0" 
                    izz="0.1"/>
        </inertial>
    </link>

    <!-- Right Wheel -->
    <link name="right_wheel">
        <visual>
            <geometry>
                <cylinder radius="0.1" length="0.05"/>
            </geometry>
            <material name="black"/>
        </visual>
        <collision>
            <geometry>
                <cylinder radius="0.1" length="0.05"/>
            </geometry>
        </collision>
        <inertial>
            <mass value="1.0"/>
            <origin xyz="0 0 0" rpy="0 0 0"/>
            <inertia ixx="0.01" ixy="0.0" ixz="0.0" 
                    iyy="0.01" iyz="0.0" 
                    izz="0.01"/>
        </inertial>
    </link>

    <!-- Left Wheel -->
    <link name="left_wheel">
        <visual>
            <geometry>
                <cylinder radius="0.1" length="0.05"/>
            </geometry>
            <material name="black"/>
        </visual>
        <collision>
            <geometry>
                <cylinder radius="0.1" length="0.05"/>
            </geometry>
        </collision>
        <inertial>
            <mass value="1.0"/>
            <origin xyz="0 0 0" rpy="0 0 0"/>
            <inertia ixx="0.01" ixy="0.0" ixz="0.0" 
                    iyy="0.01" iyz="0.0" 
                    izz="0.01"/>
        </inertial>
    </link>    

    <!-- Lift Link -->
    <link name="lift">
        <visual>
            <geometry>
                <box size="0.1 0.1 0.3"/>
            </geometry>
            <material name="red"/>
        </visual>
        <collision>
            <geometry>
                <box size="0.1 0.1 0.3"/>
            </geometry>
        </collision>
        <inertial>
            <mass value="5.0"/>
            <origin xyz="0 0 0.15" rpy="0 0 0"/>
            <inertia ixx="0.02" ixy="0.0" ixz="0.0" 
                    iyy="0.02" iyz="0.0" 
                    izz="0.02"/>
        </inertial>
    </link>

    <!-- Joints -->
    <joint name="left_wheel_joint" type="continuous">
        <parent link="base_link"/>
        <child link="left_wheel"/>
        <origin xyz="0 0.175 0" rpy="1.5708 0 0"/>
        <axis xyz="0 0 1"/>
    </joint>

    <joint name="right_wheel_joint" type="continuous">
        <parent link="base_link"/>
        <child link="right_wheel"/>
        <origin xyz="0 -0.175 0" rpy="1.5708 0 0"/>
        <axis xyz="0 0 1"/>
    </joint>

    <joint name="lift_joint" type="prismatic">
        <parent link="base_link"/>
        <child link="lift"/>
        <origin xyz="0 0 0.05"/>
        <axis xyz="0 0 1"/>
        <limit effort="1000.0" lower="0" upper="0.5" velocity="0.5"/>
    </joint>

</robot>